Workbook

Sheet Inputs
B2: Newport Wholesalers — GovCon Financial Model
B3: 5-Year Projection | February 2026
B5: NEWPORT INPUTS
B7: Current Annual Revenue | I7: Scale of gov entry relative to core business
B8: Current Gross Margin (%) | I8: Baseline for government pricing strategy
B9: Delivery Radius (miles from FL warehouse) | I9: FL only = $85M TAM. SE region = $179M TAM
B10: Refrigerated/Temp-Controlled Delivery? (Y/N) | I10: Opens or closes entire product categories
B11: # of Confectionery/Snack/Nut SKUs | I11: More SKUs = eligible for more bid opportunities
B12: Food Safety Certifications? (SQF/GFSI/FDA) | I12: $0 if certified. Up to $23.5K if not
B13: SDB/HUBZone/8(a) Eligible? (Y/N) | I13: Set-aside win rates 28% vs 8% open competition
B14: Min Profitable Order Size ($) | I14: Must be below $5,200 avg micro-purchase threshold
B15: Any Prior Gov Contract Experience? | I15: Past performance is the #1 evaluation factor
B17: WIN RATE ASSUMPTIONS
B18: Tier | C18: Yr 1 | D18: Yr 2 | E18: Yr 3 | F18: Yr 4 | G18: Yr 5 | I18: Notes
B19: Micro (<$15K) | C19: 0.15 | D19: 0.2 | E19: 0.22 | F19: 0.25 | G19: 0.25 | I19: GPC credit card - low barrier, high volume
B20: Simplified ($15K-$250K) | C20: 0.05 | D20: 0.1 | E20: 0.14 | F20: 0.17 | G20: 0.2 | I20: Starts Q3 Y1 with past perf refs
B21: Set-Aside (SDB/HUBZone) | C21: 0.15 | D21: 0.22 | E21: 0.28 | F21: 0.32 | G21: 0.35 | I21: IF certified. Day 1 eligible
B22: SLED (State/Local/Ed) | C22: 0.08 | D22: 0.12 | E22: 0.16 | F22: 0.2 | G22: 0.22 | I22: Relationship-driven, FL focus
B23: Sealed Bid ($250K+) | C23: 0 | D23: 0.03 | E23: 0.06 | F23: 0.09 | G23: 0.12 | I23: Requires established track record
B24: Recompete/Renewal Rate | C24: 0.7 | I24: 70% of contracts renew to incumbent
B26: COST & MARGIN ASSUMPTIONS
B27: Metric | C27: Value | I27: Notes
B28: Blended Gross Margin | C28: 0.22 | I28: 22% weighted avg across tiers
B29: Bid Prep Cost (Simplified+ per bid) | C29: 750 | I29: Staff time + materials per RFQ/RFP
B30: Fulfillment Overhead (% of rev) | C30: 0.03 | I30: Compliance, logistics, admin
B32: RENEWAL AVG CONTRACT VALUE
B33: Metric | C33: Yr 1 | D33: Yr 2 | E33: Yr 3 | F33: Yr 4 | G33: Yr 5 | I33: Logic
B34: Avg Renewal Contract Value | C34: 8000 | D34: 15000 | E34: 25000 | F34: 35000 | G34: 42000 | I34: Early = micro renewals. Later = simplified+ renewals
B36: ANNUAL PROGRAM INVESTMENT
B37: Item | C37: Yr 1 | D37: Yr 2 | E37: Yr 3 | F37: Yr 4 | G37: Yr 5 | H37: Total | I37: Includes
B38: Program Investment | C38: 11000 | D38: 6000 | E38: 5000 | F38: 4000 | G38: 4000 | H38: =SUM(C38:G38) | I38: Assoc dues, conferences, travel, software, insurance adj, legal review

Sheet Two Routes
B2: Newport Wholesalers — GovCon Financial Model
B3: 5-Year Projection | February 2026
B5: COST COMPARISON
B6: Item | C6: FREE ROUTE | E6: PAID ROUTE | G6: WHY
B7: SAM.gov Registration | C7: $0 | E7: $0 | G7: Required - both routes
B8: FL MyFloridaMarketplace | C8: $0 | E8: $0 | G8: Required for SLED
B9: Capability Statement | C9: DIY ($0) | E9: $500-$2,000 | G9: Professional version wins more
B10: Food Safety Certification | C10: Existing ($0) | E10: $0-$23,500 | G10: $0 if already certified
B11: Attorney Review (2-3 contracts) | C11: Skip | E11: $2,500-$5,000 | G11: Gov contracts differ from commercial
B12: Insurance Adjustment | C12: Current ($0) | E12: $1,500-$3,000 | G12: Some contracts need higher limits
B13: Industry Associations (NRA/IFDA) | C13: Skip | E13: $1,000-$2,500 | G13: Bid alerts + networking access
B14: Trade Shows (2 events) | C14: Skip | E14: $3,000-$6,000 | G14: Face time with contracting officers
B15: Relationship Building | C15: Cold calls ($0) | E15: $2,000-$5,000 | G15: CO meetings, base/facility visits
B16: Bid Tracking Software | C16: Manual / free | E16: $500-$1,500 | G16: GovWin IQ or similar
B17: TOTAL YEAR 1 | C17: $0 - $2,000 | E17: $11,000 - $47,000 | G17: No consulting fee - tools/hard costs only
B19: EXPECTED OUTCOMES
B20: Metric | C20: Free | E20: Paid | G20: Delta
B21: Yr 1 Win Rate (Micro) | C21: 8-10% | E21: 12-18% | G21: +50-80%
B22: Yr 1 Contracts Won | C22: 4-6 | E22: 10-15 | G22: 2-3x more
B23: Yr 1 Revenue | C23: $25K-$45K | E23: $80K-$150K | G23: 3-5x
B24: Time to Simplified Eligibility | C24: 18-24 months | E24: 6-9 months | G24: 1+ year faster
B25: 5-Yr Cumulative Revenue | C25: $400K-$800K | E25: $3M-$6M+ | G25: 8-10x
B26: 5-Yr Cumulative Owner Earnings | C26: $50K-$120K | E26: $500K-$900K+ | G26: 10x+
B28: RECOMMENDATION: Paid route. Year 1 is a small net investment that pays for itself by mid-Year 2. The compounding renewal base means every Year 1 dollar multiplies through Years 2-5.

Sheet 5-Year Model
B2: Newport Wholesalers — GovCon Financial Model
B3: 5-Year Projection | February 2026
B5: NEW BIDS SUBMITTED
B6: Blue values are editable assumptions
C7: Yr 1 | D7: Yr 2 | E7: Yr 3 | F7: Yr 4 | G7: Yr 5 | H7: Total | I7: Strategy
B8: Micro (<$15K) CREDIBILITY PHASE | C8: 55 | D8: 25 | E8: 10 | F8: 0 | G8: 0 | H8: =SUM(C8:G8) | I8: Win enough to unlock, then stop actively bidding
B9: Simplified ($15K-$250K) | C9: 8 | D9: 28 | E9: 42 | F9: 52 | G9: 58 | H9: =SUM(C9:G9) | I9: Starts Q3 Y1 w/ past perf. Primary engine Y2+
B10: Set-Aside (SDB/HUBZone) | C10: 6 | D10: 14 | E10: 22 | F10: 28 | G10: 30 | H10: =SUM(C10:G10) | I10: Day 1 if certified. Premium margins
B11: SLED (State/Local/Ed) | C11: 15 | D11: 22 | E11: 30 | F11: 38 | G11: 42 | H11: =SUM(C11:G11) | I11: FL schools/counties - parallel from Day 1
B12: Sealed Bid ($250K+) | C12: 0 | D12: 3 | E12: 8 | F12: 12 | G12: 16 | H12: =SUM(C12:G12) | I12: Y2+ only with track record
B13: TOTAL BIDS | C13: =SUM(C8:C12) | D13: =SUM(D8:D12) | E13: =SUM(E8:E12) | F13: =SUM(F8:F12) | G13: =SUM(G8:G12) | H13: =SUM(H8:H12)
B15: NEW CONTRACT WINS
C16: Yr 1 | D16: Yr 2 | E16: Yr 3 | F16: Yr 4 | G16: Yr 5 | H16: Total | I16: Strategy
B17: Micro (<$15K) | C17: =ROUND(C8*Inputs!C19,0) | D17: =ROUND(D8*Inputs!D19,0) | E17: =ROUND(E8*Inputs!E19,0) | F17: =ROUND(F8*Inputs!F19,0) | G17: =ROUND(G8*Inputs!G19,0) | H17: =SUM(C17:G17)
B18: Simplified ($15K-$250K) | C18: =ROUND(C9*Inputs!C20,0) | D18: =ROUND(D9*Inputs!D20,0) | E18: =ROUND(E9*Inputs!E20,0) | F18: =ROUND(F9*Inputs!F20,0) | G18: =ROUND(G9*Inputs!G20,0) | H18: =SUM(C18:G18)
B19: Set-Aside (SDB/HUBZone) | C19: =ROUND(C10*Inputs!C21,0) | D19: =ROUND(D10*Inputs!D21,0) | E19: =ROUND(E10*Inputs!E21,0) | F19: =ROUND(F10*Inputs!F21,0) | G19: =ROUND(G10*Inputs!G21,0) | H19: =SUM(C19:G19)
B20: SLED (State/Local/Ed) | C20: =ROUND(C11*Inputs!C22,0) | D20: =ROUND(D11*Inputs!D22,0) | E20: =ROUND(E11*Inputs!E22,0) | F20: =ROUND(F11*Inputs!F22,0) | G20: =ROUND(G11*Inputs!G22,0) | H20: =SUM(C20:G20)
B21: Sealed Bid ($250K+) | C21: =ROUND(C12*Inputs!C23,0) | D21: =ROUND(D12*Inputs!D23,0) | E21: =ROUND(E12*Inputs!E23,0) | F21: =ROUND(F12*Inputs!F23,0) | G21: =ROUND(G12*Inputs!G23,0) | H21: =SUM(C21:G21)
B22: TOTAL NEW WINS | C22: =SUM(C17:C21) | D22: =SUM(D17:D21) | E22: =SUM(E17:E21) | F22: =SUM(F17:F21) | G22: =SUM(G17:G21) | H22: =SUM(H17:H21)
B24: ACTIVE CONTRACT BASE
B25: 70% renewal rate compounds the portfolio each year
C26: Yr 1 | D26: Yr 2 | E26: Yr 3 | F26: Yr 4 | G26: Yr 5 | H26: Total | I26: Strategy
B27: Renewed from Prior Year (70%) | C27: 0 | D27: =ROUND(C29*Inputs!$C$24,0) | E27: =ROUND(D29*Inputs!$C$24,0) | F27: =ROUND(E29*Inputs!$C$24,0) | G27: =ROUND(F29*Inputs!$C$24,0) | H27: =SUM(C27:G27)
B28: + New Wins This Year | C28: =C22 | D28: =D22 | E28: =E22 | F28: =F22 | G28: =G22 | H28: =SUM(C28:G28)
B29: TOTAL ACTIVE CONTRACTS | C29: =C27+C28 | D29: =D27+D28 | E29: =E27+E28 | F29: =F27+F28 | G29: =G27+G28 | H29: =SUM(C29:G29)
B31: REVENUE
B32: Source | C32: Yr 1 | D32: Yr 2 | E32: Yr 3 | F32: Yr 4 | G32: Yr 5 | H32: 5-Yr Total | I32: Avg Contract
B33: Micro Wins (new) | C33: =C17*$I$33 | D33: =D17*$I$33 | E33: =E17*$I$33 | F33: =F17*$I$33 | G33: =G17*$I$33 | H33: =SUM(C33:G33) | I33: 5200
B34: Simplified Wins (new) | C34: =C18*$I$34 | D34: =D18*$I$34 | E34: =E18*$I$34 | F34: =F18*$I$34 | G34: =G18*$I$34 | H34: =SUM(C34:G34) | I34: 45000
B35: Set-Aside Wins (new) | C35: =C19*$I$35 | D35: =D19*$I$35 | E35: =E19*$I$35 | F35: =F19*$I$35 | G35: =G19*$I$35 | H35: =SUM(C35:G35) | I35: 40000
B36: SLED Wins (new) | C36: =C20*$I$36 | D36: =D20*$I$36 | E36: =E20*$I$36 | F36: =F20*$I$36 | G36: =G20*$I$36 | H36: =SUM(C36:G36) | I36: 18000
B37: Sealed Bid Wins (new) | C37: =C21*$I$37 | D37: =D21*$I$37 | E37: =E21*$I$37 | F37: =F21*$I$37 | G37: =G21*$I$37 | H37: =SUM(C37:G37) | I37: 175000
B38: Renewal Revenue (recurring) | C38: =C27*Inputs!C34 | D38: =D27*Inputs!D34 | E38: =E27*Inputs!E34 | F38: =F27*Inputs!F34 | G38: =G27*Inputs!G34 | H38: =SUM(C38:G38) | I38: Avg grows as portfolio shifts up
B39: TOTAL REVENUE | C39: =SUM(C33:C38) | D39: =SUM(D33:D38) | E39: =SUM(E33:E38) | F39: =SUM(F33:F38) | G39: =SUM(G33:G38) | H39: =SUM(C39:G39)
B41: OWNER EARNINGS
B42: What Newport keeps after all costs
B43: Line Item | C43: Yr 1 | D43: Yr 2 | E43: Yr 3 | F43: Yr 4 | G43: Yr 5 | H43: 5-Yr Total
B44: Revenue | C44: =C39 | D44: =D39 | E44: =E39 | F44: =F39 | G44: =G39 | H44: =SUM(C44:G44)
B45: (-) COGS | C45: =C44*(1-Inputs!$C$28) | D45: =D44*(1-Inputs!$C$28) | E45: =E44*(1-Inputs!$C$28) | F45: =F44*(1-Inputs!$C$28) | G45: =G44*(1-Inputs!$C$28) | H45: =SUM(C45:G45)
B46: Gross Profit (22%) | C46: =C44-C45 | D46: =D44-D45 | E46: =E44-E45 | F46: =F44-F45 | G46: =G44-G45 | H46: =SUM(C46:G46)
...

Sheet Market Analysis
B2: Newport Wholesalers — GovCon Financial Model
B3: 5-Year Projection | February 2026
B5: ADDRESSABLE MARKET WATERFALL
B6: Level | C6: Scope | D6: Annual $ | E6: # Awards | F6: Avg Size | G6: Newport Fit
B7: Federal Food (National) | C7: All NAICS 311/424 | D7: 7200000000 | E7: ~500K | F7: $14.4K | G7: NOT REALISTIC
B8: Federal (<$350K) | C8: Realistic bid range | D8: 2100000000 | E8: ~300K | F8: $7K | G8: Too broad
B9: Florida Federal (<$350K) | C9: Home state | D9: 85000000 | E9: 39,685 | F9: $2.1K | G9: ADDRESSABLE
B10: Southeast (<$350K) | C10: FL+GA+SC+AL+MS | D10: 179000000 | E10: ~80K | F10: $2.2K | G10: IF multi-state
B11: FL + SLED Combined | C11: Fed + State/Local | D11: 135000000 | E11: ~55K | F11: $2.5K | G11: TOTAL OPP
B13: Chart Data | C13: $M Annual
B14: National (<$350K) | C14: 2100
B15: Florida | C15: 85
B16: Southeast | C16: 179
B17: FL+SLED | C17: 135
B18: Confectionery Gap | C18: 55
B34: REAL CONTRACT EXAMPLES
B35: Tier | C35: Agency | D35: Value | E35: Location | F35: Product | G35: Frequency
B36: Micro | C36: USDA Forest Service | D36: $3,800 | E36: Ocala NF, FL | F36: Trail mix/snacks | G36: Quarterly
B37: Micro | C37: VA Medical Center | D37: $4,200 | E37: Bay Pines, FL | F37: Candy/confectionery | G37: Monthly
B38: Micro | C38: DeCA Commissary | D38: $8,500 | E38: MacDill AFB, FL | F38: Snack assortment | G38: Monthly
B39: Micro | C39: DOD Elementary | D39: $5,100 | E39: Patrick SFB, FL | F39: Snack packs | G39: Weekly
B40: Set-Aside | C40: BOP Coleman | D40: $28,000 | E40: Sumterville, FL | F40: Commissary snacks | G40: Monthly
B41: Set-Aside | C41: BOP Miami FDC | D41: $35,000 | E41: Miami, FL | F41: Dry goods bundle | G41: Monthly
B42: Simplified | C42: School District | D42: $65,000 | E42: Broward County | F42: Snack program | G42: Annual
B43: Simplified | C43: State DOC | D43: $85,000 | E43: FL Corrections | F43: Commissary supply | G43: Annual
B44: SLED | C44: County Gov | D44: $42,000 | E44: Palm Beach, FL | F44: Event concessions | G44: Seasonal
B45: SLED | C45: State University | D45: $55,000 | E45: FSU, Tallahassee | F45: Vending supply | G45: Annual
B46: Sealed Bid | C46: DeCA Regional | D46: $220,000 | E46: SE Region | F46: Full confectionery line | G46: Annual
B48: CATEGORY ADVANTAGE
B49: PSC Category | C49: National TAM | D49: FL Competition | E49: Gap | F49: Priority
B50: 8925 Confectionery/Nuts | C50: 55000000 | D50: 412000 | E50: =C50-D50 | F50: WIDE OPEN
B51: 8940 Snack Foods | C51: 38000000 | D51: 2100000 | E51: =C51-D51 | F51: Strong
B52: 8950 Bakery/Cereal | C52: 31000000 | D52: 950000 | E52: =C52-D52 | F52: Good
B53: 8945 Beverages (non-alc) | C53: 22000000 | D53: 1800000 | E53: =C53-D53 | F53: Moderate
B70: COMPETITIVE LANDSCAPE
B71: Competitor | C71: Gov Rev | D71: Categories | E71: Strength | F71: Weakness | G71: Threat
B72: Oakes Farms | C72: $26M | D72: Produce/meats | E72: Established | F72: No confectionery | G72: LOW
B73: US Foods | C73: $24M | D73: Full-line | E73: Scale | F73: Ignores micro | G73: LOW
B74: Rainmaker Inc. | C74: $5M | D74: DOJ/BOP | E74: Incumbent | F74: Narrow catalog | G74: TARGET
B75: Sysco Gov | C75: $18M | D75: Institutional | E75: National | F75: Not micro-focused | G75: LOW
...

Sheet Key Questions
B2: Newport Wholesalers — GovCon Financial Model
B3: 5-Year Projection | February 2026
B5: CRITICAL DECISIONS THAT CHANGE THE MODEL
B6: Priority | C6: Question | D6: If Yes | E6: If No
B7: 1 HIGHEST | C7: Can Newport profitably fulfill orders under $5,200? | D7: Micro channel opens (83% of awards). Credibility ramp starts. | E7: Must skip to Simplified - harder, slower entry path
B8: 2 HIGHEST | C8: Eligible for SDB/HUBZone/8(a) set-aside? | D8: Win rates 28%+, margins 25%. Available from Day 1. | E8: Open competition only - lower win rates, slower ramp
B9: 3 HIGH | C9: Delivery radius from FL warehouses? | D9: FL only = $85M. SE region = $179M. Determines total addressable. | E9: We right-size model to actual reach
B10: 4 HIGH | C10: Existing food safety certs (SQF/GFSI)? | D10: Year 1 investment drops by $23,500 | E10: Biggest single cost variable
B11: 5 HIGH | C11: Willing to invest $11K-$47K (Paid Route)? | D11: Full competitive capability from Day 1. ROI positive by mid-Y2. | E11: Free route works but 12-18 months slower to traction
B12: 6 MEDIUM | C12: How many confectionery/snack/nut SKUs? | D12: Broader catalog = eligible for more bids across categories | E12: We focus on strongest categories only
B13: 7 MEDIUM | C13: Can add delivery routes to bases/prisons? | D13: DOJ/BOP channel opens ($5M+ FL). Rainmaker Inc. is beatable. | E13: Skip DOJ, focus DeCA commissaries instead
B14: 8 MEDIUM | C14: Current commercial gross margin? | D14: Calibrates if gov margins (18-25%) are accretive or dilutive | E14: May not be worth pursuing if commercial margins much higher
B15: 9 INFO | C15: Any prior gov contract experience? | D15: Past performance references accelerate everything | E15: Start from zero - typical for new entrants
B16: 10 INFO | C16: Goal: supplemental revenue or primary channel? | D16: Aggressive staffing and investment trajectory | E16: Conservative side channel approach
