Workbook

Sheet Inputs
B2: Newport Wholesalers — Commercial SDR Model
B3: 12-Month Projection | February 2026
B5: NEWPORT BUSINESS INPUTS
B6: Newport provides these values (yellow = Newport input)
B7: Metric | C7: Value | H7: Notes
B8: Avg Deal Size by Segment | C8: 50000 | D8: 25000 | E8: 15000 | F8: 30000 | G8: 20000 | H8: Seg A / B / C / D / E (Newport provides actuals)
C9: Seg A | D9: Seg B | E9: Seg C | F9: Seg D | G9: Seg E
B10: Current Gross Margin | C10: 0.22 | H10: Blended margin on commercial deals
B11: Close Rate on Warm Introductions | C11: 0.25 | H11: Baseline for comparison with cold outreach
B12: Number of Sales Reps | C12: 2 | H12: Reps handling inbound meetings from SDR
B13: Monthly Meeting Capacity per Rep | C13: 20 | H13: Max new meetings one rep can handle per month
B15: OUTREACH PARAMETERS
B16: Blue values are editable assumptions
B17: Parameter | C17: Value | H17: Notes
B18: Emails per Day per Mailbox | C18: 30 | H18: Industry best practice: 30-50/day for deliverability
B19: Number of Mailboxes | C19: 3 | H19: Each mailbox = separate sending domain
B20: Email Open Rate | C20: 0.22 | H20: B2B benchmark: 18-25%
B21: Reply Rate | C21: 0.035 | H21: Cold email benchmark: 2-5%
B22: Reply-to-Meeting Conversion | C22: 0.35 | H22: 35% of positive replies book a meeting
B23: Meeting-to-Deal Close Rate | C23: 0.18 | H23: Cold outreach close rate (lower than warm)
B24: Avg Sales Cycle (days) | C24: 45 | H24: Days from first meeting to closed deal
B26: TOOL COSTS BY SCENARIO
B27: Tool | C27: Free | D27: Moderate | E27: Aggressive | H27: Notes
B28: Apollo.io | C28: 0 | D28: 588 | E28: 1428 | H28: Free search; paid = more reveal credits
B29: Instantly | C29: 0 | D29: 444 | E29: 1164 | H29: Email automation platform
B30: Clay | C30: 0 | D30: 0 | E30: 4680 | H30: Data enrichment & workflow
B31: Twilio SMS | C31: 0 | D31: 0 | E31: 600 | H31: SMS follow-up (usage-based)
B32: Retell AI Voice | C32: 0 | D32: 0 | E32: 1200 | H32: AI voice outreach (usage-based)
B33: TOTAL ANNUAL | C33: =SUM(C28:C32) | D33: =SUM(D28:D32) | E33: =SUM(E28:E32)
B35: CAPACITY BY SCENARIO
B36: Scenario | C36: Prospects/Week | D36: Prospects/Month | E36: Method
B37: Free | C37: 50 | D37: =C37*4.33 | E37: Manual LinkedIn + Apollo search
B38: Moderate | C38: 450 | D38: =C38*4.33 | E38: Email automation (Instantly)
B39: Aggressive | C39: 900 | D39: =C39*4.33 | E39: Multi-channel (email + SMS + voice)
B41: WEIGHTED AVERAGE DEAL SIZE
B42: Computed from segment deal sizes (equal weight)
B43: Weighted Avg Deal Size | C43: =AVERAGE(C8:G8) | H43: Average across 5 segments

Sheet ICP Segments
B2: Newport Wholesalers — Commercial SDR Model
B3: 12-Month Projection | February 2026
B5: ICP SEGMENT ECONOMICS
B6: Metric | C6: Seg A: Enterprise Grocery | D6: Seg B: Manufacturers | E6: Seg C: Gov Buyers | F6: Seg D: Corrections | G6: Seg E: Candy/Confectionery
B7: Pipeline Type | C7: Direct-to-customer | D7: Partner | E7: Direct-to-customer | F7: Direct-to-customer | G7: Partner
B8: Geography | C8: US/UK/EU | D8: US/UK/EU | E8: US only | F8: US only | G8: US/LATAM
B9: Est. Addressable Companies | C9: 2000 | D9: 3000 | E9: 500 | F9: 200 | G9: 1831
B10: Apollo Coverage | C10: 0.65 | D10: 0.6 | E10: 0.4 | F10: 0.55 | G10: 0.6
B11: Contacts per Company | C11: 3 | D11: 3 | E11: 3 | F11: 3 | G11: 3
B12: Reachable Contacts | C12: =ROUND(C9*C10*C11,0) | D12: =ROUND(D9*D10*D11,0) | E12: =ROUND(E9*E10*E11,0) | F12: =ROUND(F9*F10*F11,0) | G12: =ROUND(G9*G10*G11,0)
B14: Avg Deal Size | C14: =Inputs!C8 | D14: =Inputs!D8 | E14: =Inputs!E8 | F14: =Inputs!F8 | G14: =Inputs!G8
B15: Gross Margin | C15: =Inputs!C10 | D15: =Inputs!C10 | E15: =Inputs!C10 | F15: =Inputs!C10 | G15: =Inputs!C10
B16: Est. Annual Revenue per Deal | C16: =C14 | D16: =D14 | E16: =E14 | F16: =F14 | G16: =G14
B17: Gross Profit per Deal | C17: =C16*C15 | D17: =D16*D15 | E17: =E16*E15 | F17: =F16*F15 | G17: =G16*G15
B19: Segment Priority | C19: 1 | D19: 2 | E19: 3 | F19: 3 | G19: 1
B20: Notes | C20: Largest deal size | D20: Volume play | E20: Overlap with GovCon channel | F20: Niche, high barriers | G20: Newport's specialty
B22: SEGMENT TAM SUMMARY
B23: Metric | C23: Seg A | D23: Seg B | E23: Seg C | F23: Seg D | G23: Seg E
B24: Segment TAM (companies x deal) | C24: =C9*C14 | D24: =D9*D14 | E24: =E9*E14 | F24: =F9*F14 | G24: =G9*G14
B25: Reachable TAM (Apollo-filtered) | C25: =ROUND(C12/C11,0)*C14 | D25: =ROUND(D12/D11,0)*D14 | E25: =ROUND(E12/E11,0)*E14 | F25: =ROUND(F12/F11,0)*F14 | G25: =ROUND(G12/G11,0)*G14

Sheet Funnel Model
B2: Newport Wholesalers — Commercial SDR Model
B3: 12-Month Projection | February 2026
B5: FREE SCENARIO
B6: Metric | C6: M1 | D6: M2 | E6: M3 | F6: M4 | G6: M5 | H6: M6 | I6: M7 | J6: M8 | K6: M9 | L6: M10 | M6: M11 | N6: M12 | O6: Total
B7: Prospects Contacted | C7: =ROUND(Inputs!D37,0) | D7: =ROUND(Inputs!D37,0) | E7: =ROUND(Inputs!D37,0) | F7: =ROUND(Inputs!D37,0) | G7: =ROUND(Inputs!D37,0) | H7: =ROUND(Inputs!D37,0) | I7: =ROUND(Inputs!D37,0) | J7: =ROUND(Inputs!D37,0) | K7: =ROUND(Inputs!D37,0) | L7: =ROUND(Inputs!D37,0) | M7: =ROUND(Inputs!D37,0) | N7: =ROUND(Inputs!D37,0) | O7: =SUM(C7:N7)
B8: Opens | C8: =ROUND(C7*Inputs!C20,0) | D8: =ROUND(D7*Inputs!C20,0) | E8: =ROUND(E7*Inputs!C20,0) | F8: =ROUND(F7*Inputs!C20,0) | G8: =ROUND(G7*Inputs!C20,0) | H8: =ROUND(H7*Inputs!C20,0) | I8: =ROUND(I7*Inputs!C20,0) | J8: =ROUND(J7*Inputs!C20,0) | K8: =ROUND(K7*Inputs!C20,0) | L8: =ROUND(L7*Inputs!C20,0) | M8: =ROUND(M7*Inputs!C20,0) | N8: =ROUND(N7*Inputs!C20,0) | O8: =SUM(C8:N8)
B9: Replies | C9: =ROUND(C7*Inputs!C21,0) | D9: =ROUND(D7*Inputs!C21,0) | E9: =ROUND(E7*Inputs!C21,0) | F9: =ROUND(F7*Inputs!C21,0) | G9: =ROUND(G7*Inputs!C21,0) | H9: =ROUND(H7*Inputs!C21,0) | I9: =ROUND(I7*Inputs!C21,0) | J9: =ROUND(J7*Inputs!C21,0) | K9: =ROUND(K7*Inputs!C21,0) | L9: =ROUND(L7*Inputs!C21,0) | M9: =ROUND(M7*Inputs!C21,0) | N9: =ROUND(N7*Inputs!C21,0) | O9: =SUM(C9:N9)
B10: Meetings Booked (raw) | C10: =ROUND(C9*Inputs!C22,0) | D10: =ROUND(D9*Inputs!C22,0) | E10: =ROUND(E9*Inputs!C22,0) | F10: =ROUND(F9*Inputs!C22,0) | G10: =ROUND(G9*Inputs!C22,0) | H10: =ROUND(H9*Inputs!C22,0) | I10: =ROUND(I9*Inputs!C22,0) | J10: =ROUND(J9*Inputs!C22,0) | K10: =ROUND(K9*Inputs!C22,0) | L10: =ROUND(L9*Inputs!C22,0) | M10: =ROUND(M9*Inputs!C22,0) | N10: =ROUND(N9*Inputs!C22,0) | O10: =SUM(C10:N10)
B11: Meetings (capacity-capped) | C11: =MIN(C10,Inputs!C12*Inputs!C13) | D11: =MIN(D10,Inputs!C12*Inputs!C13) | E11: =MIN(E10,Inputs!C12*Inputs!C13) | F11: =MIN(F10,Inputs!C12*Inputs!C13) | G11: =MIN(G10,Inputs!C12*Inputs!C13) | H11: =MIN(H10,Inputs!C12*Inputs!C13) | I11: =MIN(I10,Inputs!C12*Inputs!C13) | J11: =MIN(J10,Inputs!C12*Inputs!C13) | K11: =MIN(K10,Inputs!C12*Inputs!C13) | L11: =MIN(L10,Inputs!C12*Inputs!C13) | M11: =MIN(M10,Inputs!C12*Inputs!C13) | N11: =MIN(N10,Inputs!C12*Inputs!C13) | O11: =SUM(C11:N11)
B12: Deals Closed | C12: 0 | D12: 0 | E12: =ROUND(C11*Inputs!C23,0) | F12: =ROUND(D11*Inputs!C23,0) | G12: =ROUND(E11*Inputs!C23,0) | H12: =ROUND(F11*Inputs!C23,0) | I12: =ROUND(G11*Inputs!C23,0) | J12: =ROUND(H11*Inputs!C23,0) | K12: =ROUND(I11*Inputs!C23,0) | L12: =ROUND(J11*Inputs!C23,0) | M12: =ROUND(K11*Inputs!C23,0) | N12: =ROUND(L11*Inputs!C23,0) | O12: =SUM(C12:N12)
B13: Revenue | C13: =C12*Inputs!C43 | D13: =D12*Inputs!C43 | E13: =E12*Inputs!C43 | F13: =F12*Inputs!C43 | G13: =G12*Inputs!C43 | H13: =H12*Inputs!C43 | I13: =I12*Inputs!C43 | J13: =J12*Inputs!C43 | K13: =K12*Inputs!C43 | L13: =L12*Inputs!C43 | M13: =M12*Inputs!C43 | N13: =N12*Inputs!C43 | O13: =SUM(C13:N13)
B14: Gross Profit | C14: =C13*Inputs!C10 | D14: =D13*Inputs!C10 | E14: =E13*Inputs!C10 | F14: =F13*Inputs!C10 | G14: =G13*Inputs!C10 | H14: =H13*Inputs!C10 | I14: =I13*Inputs!C10 | J14: =J13*Inputs!C10 | K14: =K13*Inputs!C10 | L14: =L13*Inputs!C10 | M14: =M13*Inputs!C10 | N14: =N13*Inputs!C10 | O14: =SUM(C14:N14)
B15: Tool Costs (monthly) | C15: =ROUND(Inputs!C33/12,0) | D15: =ROUND(Inputs!C33/12,0) | E15: =ROUND(Inputs!C33/12,0) | F15: =ROUND(Inputs!C33/12,0) | G15: =ROUND(Inputs!C33/12,0) | H15: =ROUND(Inputs!C33/12,0) | I15: =ROUND(Inputs!C33/12,0) | J15: =ROUND(Inputs!C33/12,0) | K15: =ROUND(Inputs!C33/12,0) | L15: =ROUND(Inputs!C33/12,0) | M15: =ROUND(Inputs!C33/12,0) | N15: =ROUND(Inputs!C33/12,0) | O15: =SUM(C15:N15)
B16: NET CONTRIBUTION | C16: =C14-C15 | D16: =D14-D15 | E16: =E14-E15 | F16: =F14-F15 | G16: =G14-G15 | H16: =H14-H15 | I16: =I14-I15 | J16: =J14-J15 | ... N16: =N14-N15 | O16: =SUM(C16:N16)
B17: Cumulative Revenue | C17: =C13 | D17: =C17+D13 | E17: =D17+E13 | F17: =E17+F13 | G17: =F17+G13 | H17: =G17+H13 | I17: =H17+I13 | J17: =I17+J13 | K17: =J17+K13 | ... N17: =M17+N13 | O17: =N17
B19: MODERATE SCENARIO
B20: Metric | C20: M1 | D20: M2 | E20: M3 | F20: M4 | G20: M5 | H20: M6 | I20: M7 | J20: M8 | K20: M9 | L20: M10 | M20: M11 | N20: M12 | O20: Total
B21: Prospects Contacted | C21: =ROUND(Inputs!D38,0) | D21: =ROUND(Inputs!D38,0) | E21: =ROUND(Inputs!D38,0) | F21: =ROUND(Inputs!D38,0) | G21: =ROUND(Inputs!D38,0) | H21: =ROUND(Inputs!D38,0) | I21: =ROUND(Inputs!D38,0) | J21: =ROUND(Inputs!D38,0) | K21: =ROUND(Inputs!D38,0) | L21: =ROUND(Inputs!D38,0) | M21: =ROUND(Inputs!D38,0) | N21: =ROUND(Inputs!D38,0) | O21: =SUM(C21:N21)
B22: Opens | C22: =ROUND(C21*Inputs!C20,0) | D22: =ROUND(D21*Inputs!C20,0) | E22: =ROUND(E21*Inputs!C20,0) | F22: =ROUND(F21*Inputs!C20,0) | G22: =ROUND(G21*Inputs!C20,0) | H22: =ROUND(H21*Inputs!C20,0) | I22: =ROUND(I21*Inputs!C20,0) | J22: =ROUND(J21*Inputs!C20,0) | K22: =ROUND(K21*Inputs!C20,0) | L22: =ROUND(L21*Inputs!C20,0) | M22: =ROUND(M21*Inputs!C20,0) | N22: =ROUND(N21*Inputs!C20,0) | O22: =SUM(C22:N22)
B23: Replies | C23: =ROUND(C21*Inputs!C21,0) | D23: =ROUND(D21*Inputs!C21,0) | E23: =ROUND(E21*Inputs!C21,0) | F23: =ROUND(F21*Inputs!C21,0) | G23: =ROUND(G21*Inputs!C21,0) | H23: =ROUND(H21*Inputs!C21,0) | I23: =ROUND(I21*Inputs!C21,0) | J23: =ROUND(J21*Inputs!C21,0) | K23: =ROUND(K21*Inputs!C21,0) | L23: =ROUND(L21*Inputs!C21,0) | M23: =ROUND(M21*Inputs!C21,0) | N23: =ROUND(N21*Inputs!C21,0) | O23: =SUM(C23:N23)
B24: Meetings Booked (raw) | C24: =ROUND(C23*Inputs!C22,0) | D24: =ROUND(D23*Inputs!C22,0) | E24: =ROUND(E23*Inputs!C22,0) | F24: =ROUND(F23*Inputs!C22,0) | G24: =ROUND(G23*Inputs!C22,0) | H24: =ROUND(H23*Inputs!C22,0) | I24: =ROUND(I23*Inputs!C22,0) | J24: =ROUND(J23*Inputs!C22,0) | K24: =ROUND(K23*Inputs!C22,0) | L24: =ROUND(L23*Inputs!C22,0) | M24: =ROUND(M23*Inputs!C22,0) | N24: =ROUND(N23*Inputs!C22,0) | O24: =SUM(C24:N24)
B25: Meetings (capacity-capped) | C25: =MIN(C24,Inputs!C12*Inputs!C13) | D25: =MIN(D24,Inputs!C12*Inputs!C13) | E25: =MIN(E24,Inputs!C12*Inputs!C13) | F25: =MIN(F24,Inputs!C12*Inputs!C13) | G25: =MIN(G24,Inputs!C12*Inputs!C13) | H25: =MIN(H24,Inputs!C12*Inputs!C13) | I25: =MIN(I24,Inputs!C12*Inputs!C13) | J25: =MIN(J24,Inputs!C12*Inputs!C13) | K25: =MIN(K24,Inputs!C12*Inputs!C13) | L25: =MIN(L24,Inputs!C12*Inputs!C13) | M25: =MIN(M24,Inputs!C12*Inputs!C13) | N25: =MIN(N24,Inputs!C12*Inputs!C13) | O25: =SUM(C25:N25)
B26: Deals Closed | C26: 0 | D26: 0 | E26: =ROUND(C25*Inputs!C23,0) | F26: =ROUND(D25*Inputs!C23,0) | G26: =ROUND(E25*Inputs!C23,0) | H26: =ROUND(F25*Inputs!C23,0) | I26: =ROUND(G25*Inputs!C23,0) | J26: =ROUND(H25*Inputs!C23,0) | K26: =ROUND(I25*Inputs!C23,0) | L26: =ROUND(J25*Inputs!C23,0) | M26: =ROUND(K25*Inputs!C23,0) | N26: =ROUND(L25*Inputs!C23,0) | O26: =SUM(C26:N26)
B27: Revenue | C27: =C26*Inputs!C43 | D27: =D26*Inputs!C43 | E27: =E26*Inputs!C43 | F27: =F26*Inputs!C43 | G27: =G26*Inputs!C43 | H27: =H26*Inputs!C43 | I27: =I26*Inputs!C43 | J27: =J26*Inputs!C43 | K27: =K26*Inputs!C43 | L27: =L26*Inputs!C43 | M27: =M26*Inputs!C43 | N27: =N26*Inputs!C43 | O27: =SUM(C27:N27)
B28: Gross Profit | C28: =C27*Inputs!C10 | D28: =D27*Inputs!C10 | E28: =E27*Inputs!C10 | F28: =F27*Inputs!C10 | G28: =G27*Inputs!C10 | H28: =H27*Inputs!C10 | I28: =I27*Inputs!C10 | J28: =J27*Inputs!C10 | K28: =K27*Inputs!C10 | L28: =L27*Inputs!C10 | M28: =M27*Inputs!C10 | N28: =N27*Inputs!C10 | O28: =SUM(C28:N28)
B29: Tool Costs (monthly) | C29: =ROUND(Inputs!D33/12,0) | D29: =ROUND(Inputs!D33/12,0) | E29: =ROUND(Inputs!D33/12,0) | F29: =ROUND(Inputs!D33/12,0) | G29: =ROUND(Inputs!D33/12,0) | H29: =ROUND(Inputs!D33/12,0) | I29: =ROUND(Inputs!D33/12,0) | J29: =ROUND(Inputs!D33/12,0) | K29: =ROUND(Inputs!D33/12,0) | L29: =ROUND(Inputs!D33/12,0) | M29: =ROUND(Inputs!D33/12,0) | N29: =ROUND(Inputs!D33/12,0) | O29: =SUM(C29:N29)
B30: NET CONTRIBUTION | C30: =C28-C29 | D30: =D28-D29 | E30: =E28-E29 | F30: =F28-F29 | G30: =G28-G29 | H30: =H28-H29 | I30: =I28-I29 | J30: =J28-J29 | ... N30: =N28-N29 | O30: =SUM(C30:N30)
B31: Cumulative Revenue | C31: =C27 | D31: =C31+D27 | E31: =D31+E27 | F31: =E31+F27 | G31: =F31+G27 | H31: =G31+H27 | I31: =H31+I27 | J31: =I31+J27 | K31: =J31+K27 | ... N31: =M31+N27 | O31: =N31
B33: AGGRESSIVE SCENARIO
B34: Metric | C34: M1 | D34: M2 | E34: M3 | F34: M4 | G34: M5 | H34: M6 | I34: M7 | J34: M8 | K34: M9 | L34: M10 | M34: M11 | N34: M12 | O34: Total
B35: Prospects Contacted | C35: =ROUND(Inputs!D39,0) | D35: =ROUND(Inputs!D39,0) | E35: =ROUND(Inputs!D39,0) | F35: =ROUND(Inputs!D39,0) | G35: =ROUND(Inputs!D39,0) | H35: =ROUND(Inputs!D39,0) | I35: =ROUND(Inputs!D39,0) | J35: =ROUND(Inputs!D39,0) | K35: =ROUND(Inputs!D39,0) | L35: =ROUND(Inputs!D39,0) | M35: =ROUND(Inputs!D39,0) | N35: =ROUND(Inputs!D39,0) | O35: =SUM(C35:N35)
B36: Opens | C36: =ROUND(C35*Inputs!C20,0) | D36: =ROUND(D35*Inputs!C20,0) | E36: =ROUND(E35*Inputs!C20,0) | F36: =ROUND(F35*Inputs!C20,0) | G36: =ROUND(G35*Inputs!C20,0) | H36: =ROUND(H35*Inputs!C20,0) | I36: =ROUND(I35*Inputs!C20,0) | J36: =ROUND(J35*Inputs!C20,0) | K36: =ROUND(K35*Inputs!C20,0) | L36: =ROUND(L35*Inputs!C20,0) | M36: =ROUND(M35*Inputs!C20,0) | N36: =ROUND(N35*Inputs!C20,0) | O36: =SUM(C36:N36)
B37: Replies | C37: =ROUND(C35*Inputs!C21,0) | D37: =ROUND(D35*Inputs!C21,0) | E37: =ROUND(E35*Inputs!C21,0) | F37: =ROUND(F35*Inputs!C21,0) | G37: =ROUND(G35*Inputs!C21,0) | H37: =ROUND(H35*Inputs!C21,0) | I37: =ROUND(I35*Inputs!C21,0) | J37: =ROUND(J35*Inputs!C21,0) | K37: =ROUND(K35*Inputs!C21,0) | L37: =ROUND(L35*Inputs!C21,0) | M37: =ROUND(M35*Inputs!C21,0) | N37: =ROUND(N35*Inputs!C21,0) | O37: =SUM(C37:N37)
B38: Meetings Booked (raw) | C38: =ROUND(C37*Inputs!C22,0) | D38: =ROUND(D37*Inputs!C22,0) | E38: =ROUND(E37*Inputs!C22,0) | F38: =ROUND(F37*Inputs!C22,0) | G38: =ROUND(G37*Inputs!C22,0) | H38: =ROUND(H37*Inputs!C22,0) | I38: =ROUND(I37*Inputs!C22,0) | J38: =ROUND(J37*Inputs!C22,0) | K38: =ROUND(K37*Inputs!C22,0) | L38: =ROUND(L37*Inputs!C22,0) | M38: =ROUND(M37*Inputs!C22,0) | N38: =ROUND(N37*Inputs!C22,0) | O38: =SUM(C38:N38)
B39: Meetings (capacity-capped) | C39: =MIN(C38,Inputs!C12*Inputs!C13) | D39: =MIN(D38,Inputs!C12*Inputs!C13) | E39: =MIN(E38,Inputs!C12*Inputs!C13) | F39: =MIN(F38,Inputs!C12*Inputs!C13) | G39: =MIN(G38,Inputs!C12*Inputs!C13) | H39: =MIN(H38,Inputs!C12*Inputs!C13) | I39: =MIN(I38,Inputs!C12*Inputs!C13) | J39: =MIN(J38,Inputs!C12*Inputs!C13) | K39: =MIN(K38,Inputs!C12*Inputs!C13) | L39: =MIN(L38,Inputs!C12*Inputs!C13) | M39: =MIN(M38,Inputs!C12*Inputs!C13) | N39: =MIN(N38,Inputs!C12*Inputs!C13) | O39: =SUM(C39:N39)
B40: Deals Closed | C40: 0 | D40: 0 | E40: =ROUND(C39*Inputs!C23,0) | F40: =ROUND(D39*Inputs!C23,0) | G40: =ROUND(E39*Inputs!C23,0) | H40: =ROUND(F39*Inputs!C23,0) | I40: =ROUND(G39*Inputs!C23,0) | J40: =ROUND(H39*Inputs!C23,0) | K40: =ROUND(I39*Inputs!C23,0) | L40: =ROUND(J39*Inputs!C23,0) | M40: =ROUND(K39*Inputs!C23,0) | N40: =ROUND(L39*Inputs!C23,0) | O40: =SUM(C40:N40)
B41: Revenue | C41: =C40*Inputs!C43 | D41: =D40*Inputs!C43 | E41: =E40*Inputs!C43 | F41: =F40*Inputs!C43 | G41: =G40*Inputs!C43 | H41: =H40*Inputs!C43 | I41: =I40*Inputs!C43 | J41: =J40*Inputs!C43 | K41: =K40*Inputs!C43 | L41: =L40*Inputs!C43 | M41: =M40*Inputs!C43 | N41: =N40*Inputs!C43 | O41: =SUM(C41:N41)
B42: Gross Profit | C42: =C41*Inputs!C10 | D42: =D41*Inputs!C10 | E42: =E41*Inputs!C10 | F42: =F41*Inputs!C10 | G42: =G41*Inputs!C10 | H42: =H41*Inputs!C10 | I42: =I41*Inputs!C10 | J42: =J41*Inputs!C10 | K42: =K41*Inputs!C10 | L42: =L41*Inputs!C10 | M42: =M41*Inputs!C10 | N42: =N41*Inputs!C10 | O42: =SUM(C42:N42)
B43: Tool Costs (monthly) | C43: =ROUND(Inputs!E33/12,0) | D43: =ROUND(Inputs!E33/12,0) | E43: =ROUND(Inputs!E33/12,0) | F43: =ROUND(Inputs!E33/12,0) | G43: =ROUND(Inputs!E33/12,0) | H43: =ROUND(Inputs!E33/12,0) | I43: =ROUND(Inputs!E33/12,0) | J43: =ROUND(Inputs!E33/12,0) | K43: =ROUND(Inputs!E33/12,0) | L43: =ROUND(Inputs!E33/12,0) | M43: =ROUND(Inputs!E33/12,0) | N43: =ROUND(Inputs!E33/12,0) | O43: =SUM(C43:N43)
B44: NET CONTRIBUTION | C44: =C42-C43 | D44: =D42-D43 | E44: =E42-E43 | F44: =F42-F43 | G44: =G42-G43 | H44: =H42-H43 | I44: =I42-I43 | J44: =J42-J43 | ... N44: =N42-N43 | O44: =SUM(C44:N44)
...

Sheet Market Analysis
B2: Newport Wholesalers — Commercial SDR Model
B3: 12-Month Projection | February 2026
B5: MARKET SIZING BY SEGMENT
B6: Segment | C6: Companies | D6: Reachable (Apollo) | E6: Avg Deal | F6: Est. TAM | G6: Notes
B7: A: Enterprise Grocery | C7: 2000 | D7: 1300 | E7: 50000 | F7: 100000000 | G7: Largest deal sizes; centralized procurement
B8: B: Manufacturers | C8: 3000 | D8: 1800 | E8: 25000 | F8: 75000000 | G8: Volume play; partner pipeline
B9: C: Gov Buyers | C9: 500 | D9: 200 | E9: 15000 | F9: 7500000 | G9: Overlap with GovCon; Apollo coverage low
B10: D: Corrections | C10: 200 | D10: 110 | E10: 30000 | F10: 6000000 | G10: Niche; high barriers but sticky contracts
B11: E: Candy/Confectionery | C11: 1831 | D11: 1099 | E11: 20000 | F11: 36620000 | G11: NAICS 424450; Newport's specialty
B12: TOTAL | C12: =SUM(C7:C11) | D12: =SUM(D7:D11) | F12: =SUM(F7:F11)
B28: CANDY WHOLESALE MARKET (NAICS 424450)
B29: Metric | C29: Value | G29: Source
B30: US Firms (NAICS 424450) | C30: 1,831 | G30: US Census Bureau
B31: US Establishments | C31: 2,357 | G31: US Census Bureau
B32: US Employees | C32: 40,279 | G32: US Census Bureau
B33: US Retail Confectionery Market | C33: $38B | G33: Grand View Research
B34: LATAM Confectionery Market | C34: $35-42B | G34: IndexBox / Mordor Intelligence
B35: NCA Member Retail Sales | C35: $54B | G35: National Confectioners Assoc.
B36: Key Trade Agreement | C36: USMCA: $0 tariff on MX candy | G36: USDA FAS
B37: CAFTA-DR | C37: Free/near-free on CA candy | G37: USDA FAS
B39: TOOL COMPARISON MATRIX
B40: Tool | C40: Purpose | D40: Monthly Cost | E40: Annual Cost | F40: Scenario | G40: Value Proposition
B41: Apollo.io (Basic) | C41: Contact search & enrichment | D41: $49 | E41: $588 | F41: Moderate | G41: Unlimited search; 900 credits/mo for email reveals
B42: Apollo.io (Pro) | C42: Advanced enrichment + intent | D42: $119 | E42: $1,428 | F42: Aggressive | G42: Buyer intent signals, advanced filters, API access
B43: Instantly (Growth) | C43: Email automation & warmup | D43: $37 | E43: $444 | F43: Moderate | G43: 1,000 active contacts; unlimited emails; warmup
B44: Instantly (Hypergrowth) | C44: Multi-account email | D44: $97 | E44: $1,164 | F44: Aggressive | G44: 25,000 contacts; 25 email accounts; A/B testing
B45: Clay | C45: Data enrichment workflows | D45: $390 | E45: $4,680 | F45: Aggressive | G45: Waterfall enrichment; 75+ data providers
B46: Twilio SMS | C46: SMS follow-up | D46: ~$50 | E46: ~$600 | F46: Aggressive | G46: Multi-channel touchpoint; high open rate
B47: Retell AI Voice | C47: AI voice outreach | D47: ~$100 | E47: ~$1,200 | F47: Aggressive | G47: AI voice agent for meeting scheduling
B49: APOLLO COVERAGE BY REGION
B50: Region | C50: Est. Coverage | G50: Notes
B51: United States | C51: 60-70% | G51: Strong coverage; major distributors well-indexed
B52: Mexico | C52: 30-50% | G52: Decent for larger companies; supplement with SIEM registry
B53: Central America | C53: 10-25% | G53: Smaller economies; supplement with trade directories
B54: South America (BR/CO/AR) | C54: 25-40% | G54: Larger markets have better coverage
B55: Caribbean | C55: 5-15% | G55: Small market; many informal businesses
B56: UK / EU | C56: 50-65% | G56: Good for enterprise; varies by country
B58: Sources: US Census Bureau (NAICS 424450), Grand View Research, Mordor Intelligence, IndexBox, USDA FAS, NCA, Apollo.io coverage estimates, specs/09-INTEGRATIONS.md. Feb 2026.

Sheet Key Questions
B2: Newport Wholesalers — Commercial SDR Model
B3: 12-Month Projection | February 2026
B5: CRITICAL DECISIONS THAT CALIBRATE THE MODEL
B6: Priority | C6: Question | D6: If Yes | E6: If No
B7: 1 HIGHEST | C7: What are actual deal sizes by customer type? | D7: Calibrates entire model. Current values are placeholders. | E7: Model uses estimates; directionally right but imprecise
B8: 2 HIGHEST | C8: What is current gross margin on wholesale deals? | D8: Determines profitability at every scenario level. | E8: 22% assumption may over- or under-state returns
B9: 3 HIGH | C9: How many sales reps will handle inbound meetings? | D9: Capacity constraint. More reps = more throughput. | E9: 2 reps cap at 40 meetings/mo; may bottleneck Aggressive
B10: 4 HIGH | C10: Which segments to prioritize first? | D10: Focus resources on 1-2 segments for faster traction. | E10: Spreading across all 5 dilutes effort and slows results
B11: 5 HIGH | C11: Willing to invest in Instantly email automation? | D11: Unlocks Moderate scenario (450/wk vs 50/wk). | E11: Free scenario only; manual LinkedIn outreach
B12: 6 MEDIUM | C12: Current close rate on warm introductions? | D12: Baseline calibration. Cold outreach typically 40-60% lower. | E12: We use 18% default for cold; adjust if warm rate known
B13: 7 MEDIUM | C13: Interest in LATAM candy import/export? | D13: Expands Seg E scope. USMCA = $0 tariff from Mexico. | E13: Focus US-only Seg E; still 1,831 firms to target
B14: 8 MEDIUM | C14: Existing CRM or sales tracking system? | D14: Integrate SDR pipeline into existing workflow. | E14: Recommend HubSpot Free CRM or Google Sheets tracker
B15: 9 INFO | C15: What does a typical sales cycle look like today? | D15: Calibrates 45-day default. Shorter = faster revenue. | E15: We keep 45-day assumption; conservative but standard
B16: 10 INFO | C16: Any existing outbound prospecting? | D16: Baseline comparison. SDR adds to existing effort. | E16: Greenfield — all SDR revenue is incremental
